Workbook
Name IG_CTRL: '[2]IG Def (7.1)'!$A:$A
Name IG_CTRL: #REF!

Sheet License
A1: License
A2: Please see our terms of use here: https://www.cisecurity.org/cis-securesuite/cis-securesuite-membership-terms-of-use/

Sheet Level 1
A1: Section # | B1: Recommendation # | C1: Title | D1: Assessment Status | E1: Description | F1: Rationale Statement | G1: Impact Statement | H1: Remediation Procedure | I1: Audit Procedure | J1: Additional Information | K1: CIS Controls | L1: CIS Safeguards 1 (v8) | M1: CIS Safeguards 2 (v8) | N1: CIS Safeguards 3 (v8) | O1: v8 IG1 | P1: v8 IG2 | Q1: v8 IG3 | R1: CIS Safeguards 1 (v7) | S1: CIS Safeguards 2 (v7) | T1: CIS Safeguards 3 (v7) | U1: v7 IG1 | V1: v7 IG2 | W1: v7 IG3 | X1: References | Y1: Default Value
A2: 1 | C2: Introduction | E2: This introduction section and the subsections herein provide informative articles which instruct on the use of the CIS Foundations and Service Category Benchmarks. No recommendations will be found in this section, just articles of relevant information. Please carefully review the articles in this introductory section and orient yourself with our structured approach to Benchmarking for Cloud Service Providers (CSPs). This approach differs from other CIS Benchmarks because: - there are too many different products/services in CSP product directories to practically cover in any one Benchmark, - architectural and design decisions will affect the scope and relevance of recommendations, and - there are a variety of methods for interfacing with CSP products and services. **Cloud Benchmarks - A Two-Step Approach to Securing Your Cloud Environments:** - **Step 1:** Start with Foundations Benchmarks. Apply as many recommendations as **practical** for your environment; "100%" 'compliance' is not always possible. Not all Foundations Benchmark recommendations can be applied at the same time, and not all recommendations will be relevant to your environment. Use the recommendation Profile Levels and your understanding of your unique environment architecture to determine which recommendations are in scope. - **Step 2:** Use the Service Category Benchmarks for service-specific defense-in-depth recommendations. Apply recommendations only for the services **IN USE** in your environment. Use the recommendation Profile Levels, and your understanding of your unique environment architecture to determine which recommendations are in scope.
A3: 1.1 | C3: CIS Microsoft Azure Foundations Benchmarks | E3: The suggested approach for securing your Microsoft Azure cloud environment is to start with the **latest version** of the CIS Microsoft Azure Foundations Benchmark. Because CSP environments are constantly changing, previous versions of the Foundations Benchmarks should not be used. Previous releases may contain incorrect product names, outdated procedures, deprecated features, and other inaccuracies. The CIS Foundations Benchmark provides prescriptive guidance for configuring a subset of Microsoft Azure Services with an emphasis on foundational, testable, and architecture agnostic settings for services. The Microsoft Azure Foundations Benchmark is what you should start with when beginning to secure your Azure environment. It is also the foundation for which all other Azure Service Category Benchmarks are built on so that as you grow your cloud presence and usage of the services offered you have the necessary guidance to securely configure your environment as it fits with your company’s policy. All CIS Benchmarks are created and maintained through consensus-based collaboration. Should you have feedback, suggested changes, or just like to get involved in the continued maintenance and development of CIS Microsoft Azure Benchmarks, please register on CIS WorkBench at https://workbench.cisecurity.org and join the CIS Microsoft Azure Benchmarks Community.
A4: 1.2 | C4: CIS Microsoft Azure Service Category Benchmarks | E4: After configuring your environment with the CIS Microsoft Azure Foundations Benchmark, we suggest pursuing defense-in-depth and service-specific recommendations for your Azure Services by reviewing the Service Category Benchmarks. The Service Category Benchmarks are being produced with the vision that recommendations for all security-relevant products/services offered by a CSP should have a 'home,' but the Foundations Benchmarks should retain the most crucial recommendations and not be made vast, intimidating, and impractical. The Service Category Benchmark recommendations should be applied **ONLY** for the CSP products and services that are actively **IN USE** in your environment. In each Service Category Benchmark, you may find that your environment uses none, or only a couple services from a list of many. Please review the services employed in your environment carefully to accurately scope the recommendations you apply. Failure to apply only the recommendations you need may introduce vulnerabilities, technical debt, and unnecessary expenses. Using the Microsoft Azure Product Directory (https://azure.microsoft.com/en-us/products/) as a source of categorical grouping of these services, our vision is to produce a full set of CIS Microsoft Azure Service Category Benchmarks to cover all security-relevant services. A list of planned and published Service Category Benchmarks for the Azure Community can be found on the community dashboard here: https://workbench.cisecurity.org/communities/72. **Your help is needed to bring this vision to life!** Please consider joining our CIS Microsoft Azure Community to contribute your expertise and knowledge in securing products and services from the Microsoft Azure product family. All CIS Benchmarks are created and maintained through consensus-based collaboration. Should you have feedback, suggested changes, or just like to get involved in the continued maintenance and development of CIS Microsoft Azure Benchmarks, please register on CIS WorkBench at https://workbench.cisecurity.org and join the CIS Microsoft Azure Benchmarks community.
A5: 1.3 | C5: Multiple Methods of Audit and Remediation | E5: Throughout the Benchmark, Audit and Remediation procedures are prescribed using up to five different methods. These multiple methods are presented for the convenience of readers who will be coming from different technical and experiential backgrounds. To perform any given Audit or Remediation, only one method needs to be performed. Not every method is available for every recommendation, and many that are available are not yet written for every recommendation. The methods presented in the Benchmark are formatted and titled as follows: - "**From Azure Portal**" - This is the administrative GUI accessed at https://portal.azure.com. - "**From Azure CLI**" - See additional detail in the next section. - "**From PowerShell**" - See additional detail in the next section. - "**From REST API**" - An Application Programming Interface (API) for HTTP operations on service endpoints. - "**From Azure Policy**" - Azure Policy provides an object-based method of evaluating configuration states and other governance detail. Information for the purpose of automating Azure Policy evaluation can be found in the "Automating with Azure Policy" section below. **Setting Up PowerShell and Azure CLI** In order to use the Azure Command Line Interface (CLI) and the Azure PowerShell methods for audit and remediation procedures, the following permissions are required for the account running the procedures: 1. Global Reader 2. Security Reader 3. Subscription Contributor 4. Key Vault Get/List privileges on Keys, Secrets, Certificates, and Certificate Authorities 5. Network allow listing for any source IP address performing the audit activities 6. Permissions to use PowerShell and Azure CLI These permissions can be directly assigned or assigned via Privileged Identity Management. The Azure CLI tool can be installed from the following location: https://docs.microsoft.com/en-us/cli/azure/install-azure-cli-windows?tabs=azure-cli For PowerShell, the following cmdlets are required: 1. Azure PowerShell: https://docs.microsoft.com/en-us/powershell/azure/install-az-ps-msi?view=azps-12.2.0 1. Microsoft Graph PowerShell: https://learn.microsoft.com/en-us/powershell/microsoftgraph/installation?view=graph-powershell-1.0 **Authenticating with Azure CLI** Run the following command from either PowerShell or command prompt: ``` az login --tenant <tenant id> --subscription <subscription ID> ``` **Authenticating with PowerShell** Login to the Azure tenant and subscription using the following command: ``` Connect-AzAccount ``` If you receive a message indicating `InteractiveBrowserCredential authentication failed`, disable web account manager (WAM) to force a browser authentication with the following command: ``` Update-AzConfig -EnableLoginByWam $false ``` Then attempt using 'Connect-AzAccount' again. If the browser-based login is not available, you may need to use device-code authentication, but this should be avoided and is not recommended because it is a persistent authentication method and specifically blocked by recommendations found in the Azure Benchmarks. Instructions for this method will not be provided as it is not recommended. For the Graph PowerShell module, the log in method is the same. ``` Connect-MgGraph ```
A6: 1.4 | C6: Automating with Azure Policy | E6: Azure Policy provides built-in objects ("Policy Definitions") and a platform for "Policy as Code" that can be used to evaluate and/or enforce configuration states for individual resources or groups of resources. Where a relevant Azure Policy Definition or multiple Policy Definitions have been identified as applicable to a recommendation in this Benchmark, the Policy ID(s) and associated Policy Name will be listed in the "From Azure Policy" method header. Interfacing with Azure Policy can be performed through the Azure Portal, Azure CLI, Azure PowerShell, REST API, Azure Resource Manager, Bicep, Terraform, or using GitHub Actions. Azure Policy Definitions can be batched together and structured using an "Initiative Definition" (aka: "Initiative" or "Compliance Initiative" or "Policy Set") which is constructed in a JSON file. Scoping and filtering an Azure Policy Initiative is necessary to ensure that the query is relevant to the architecture and requirements of an organization. Microsoft provides some pre-built Initiative Definitions as a starting point intended to assist in achieving governance and compliance objectives - from Security Frameworks to CIS Benchmarks. These pre-built Initiative Definitions provide a structured set of Policy Definitions with additional metadata to evaluate resource states and configurations, then present the results in an easily readable format. While the Initiatives are a very valuable starting point, they will likely require additional attention for your specific environment, so it is a valuable investment in time to understand how to interact with them to create, remove, update, and delete policy definitions and modify enforcement effects. With some effort and care, policies within an initiative which start by default in an "audit" or "auditIfNotExists" effect can be matured into enforcement effects of "deny," "modify," or "deployIfNotExists" but each individual Policy Definition should be well understood before modifying the effect. In environments that have an advanced posture and custom policy needs, custom Policy Definitions can be created for specialized resource evaluations. Building an Initiative Definition that fits the needs of your organization is generally a great way to improve overall security posture and has the potential to bring and keep your organization closer to compliance and best practice standards. **NOTE On Outdated Policy Initiatives of CIS Benchmarks:** CIS is aware that outdated versions of the CIS Benchmark are made available through the built-in Policy Initiatives offered in Azure. We always recommend using only the **latest available version** of the CIS Microsoft Azure Foundations Benchmark at all times and **using the latest published version of this Benchmark to update and maintain the policy initiative in your environments**. Cloud service provider environments are in a constant state of change, so best practice guidance - including Azure Policy recommendations - is also in a constant state of reconsideration and possible change. **General references for Azure Policy:** - Microsoft Learn - General Azure Policy Documentation: https://learn.microsoft.com/en-us/azure/governance/policy/ - Designing Policy as Code workflows: https://learn.microsoft.com/en-us/azure/governance/policy/concepts/policy-as-code - Retrieving Azure Policy information: https://learn.microsoft.com/en-us/azure/governance/policy/how-to/get-compliance-data - AzPolicyAdvertizer - a very well curated database of Azure Policy Definitions, Initiatives, and related material: https://www.azadvertizer.net/azpolicyadvertizer_all.html **Azure Policy GUI** - The Azure Policy GUI interface can be found in the Azure Admin Portal - simply search for `Policy` and select the Policy service. **Azure Policy from Azure CLI** - Azure CLI commands: https://learn.microsoft.com/en-us/cli/azure/policy?view=azure-cli-latest **Azure Policy from PowerShell** - PowerShell commands: https://learn.microsoft.com/en-us/powershell/module/az.resources#policy **Azure Policy from REST API** - REST API reference: https://learn.microsoft.com/en-us/rest/api/policy/ **Azure Policy from GitHub Actions** - Azure Policy GitHub Actions: https://github.com/marketplace/actions/azure-policy-compliance-scan **Azure Policy from Terraform** - Provider: azurerm - Reference: https://registry.terraform.io/providers/hashicorp/azurerm/latest/docs/resources/policy_definition
A7: 2 | C7: Analytics Services | E7: To better understand the relationship between the Foundations Benchmark and Services Benchmarks, please read the "Introduction" section of this document. Azure Product Directory Reference: https://azure.microsoft.com/en-us/products#analytics **FEEDBACK REQUEST:** Is there a specific service or recommendation in this section that you'd like to see addressed or improved? Let us know by making a ticket or starting a discussion in the CIS Microsoft Azure Community (https://workbench.cisecurity.org/communities/72).
A8: 2.1 | C8: Azure Databricks
A9: 2.1 | B9: 2.1.1 | C9: Ensure that Azure Databricks is deployed in a customer-managed virtual network (VNet) | D9: Automated | E9: Networking for Azure Databricks can be set up in a few different ways. Using a customer-managed Virtual Network (VNet) (also known as VNet Injection) ensures that compute clusters and control planes are securely isolated within the organization’s network boundary. By default, Databricks creates a managed VNet, which provides limited control over network security policies, firewall configurations, and routing. | F9: Using a customer-managed VNet ensures better control over network security and aligns with zero-trust architecture principles. It allows for: - Restricted outbound internet access to prevent unauthorized data exfiltration. - Integration with on-premises networks via VPN or ExpressRoute for hybrid connectivity. - Fine-grained NSG policies to restrict access at the subnet level. - Private Link for secure API access, avoiding public internet exposure. | G9: '- Requires additional configuration during Databricks workspace deployment. - Might increase operational overhead for network maintenance. - May impact connectivity if misconfigured (e.g., restrictive NSG rules or missing routes). | H9: **Remediate from Azure Portal** 1. Delete the existing Databricks workspace (migration required). 1. Create a new Databricks workspace with VNet Injection: 1. Go to Azure Portal → Create Databricks Workspace. 1. Select Advanced Networking. 1. Choose Deploy into your own Virtual Network. 1. Specify a customer-managed VNet and associated subnets. 1. Enable Private Link for secure API access. **Remediate from Azure CLI** Deploy a new Databricks workspace in a custom VNet: ``` az databricks workspace create --name <databricks-workspace-name> \ --resource-group <resource-group-name> \ --location <region> \ --managed-resource-group <managed-rg-name> \ --enable-no-public-ip true \ --network-security-group-rule "NoAzureServices" \ --public-network-access Disabled \ --custom-virtual-network-id /subscriptions/<subscription-id>/resourceGroups/<resource-group-name>/providers/Microsoft.Network/virtualNetworks/<vnet-name> ``` Ensure NSG Rules are correctly configured: ``` az network nsg rule create --resource-group <resource-group-name> \ --nsg-name <nsg-name> \ --name "DenyAllOutbound" \ --direction Outbound \ --access Deny \ --priority 4096 ``` **Remediate from PowerShell** ``` New-AzDatabricksWorkspace -ResourceGroupName <resource-group-name> -Name <databricks-workspace-name> -Location <region> -ManagedResourceGroupName <managed-rg-name> -CustomVirtualNetworkId "/subscriptions/<subscription-id>/resourceGroups/<resource-group-name>/providers/Microsoft.Network/virtualNetworks/<vnet-name>" ``` | I9: **Audit from Azure Portal** 1. Go to Azure Portal → Search for Databricks Workspaces. 1. Select the Databricks Workspace to audit. 1. Under Networking, check if the workspace is deployed in a Customer-Managed VNet. 1. If the Virtual Network field shows Databricks-Managed VNet, it is non-compliant. 1. Verify NSG rules and Private Endpoints for fine-grained access control. **Audit from Azure CLI** Run the following command to check if Databricks is using a customer-managed VNet: ``` az network vnet show --resource-group <resource-group-name> --name <vnet-name> ``` Ensure that Databricks subnets are present in the VNet configuration. Validate NSG rules attached to the Databricks subnets. **Audit from PowerShell** ``` Get-AzDatabricksWorkspace -ResourceGroupName <resource-group-name> -Name <databricks-workspace-name> | Select-Object VirtualNetworkId ``` If VirtualNetworkId is null or shows a Databricks-Managed VNet, it is non-compliant. **Audit from Azure Policy** If referencing a digital copy of this Benchmark, clicking a Policy ID will open a link to the associated Policy definition in Azure. If referencing a printed copy, you can search Policy IDs from this URL: https://portal.azure.com/#view/Microsoft_Azure_Policy/PolicyMenuBlade/~/Definitions - **Policy ID:** [9c25c9e4-ee12-4882-afd2-11fb9d87893f](https://portal.azure.com/#view/Microsoft_Azure_Policy/PolicyDetailBlade/definitionId/%2Fproviders%2FMicrosoft.Authorization%2FpolicyDefinitions%2F9c25c9e4-ee12-4882-afd2-11fb9d87893f) **- Name:** 'Azure Databricks Workspaces should be in a virtual network' | K9: TITLE:Establish and Maintain a Secure Network Architecture CONTROL:v8 12.2 DESCRIPTION:Establish and maintain a secure network architecture. A secure network architecture must address segmentation, least privilege, and availability, at a minimum.;TITLE:Segment the Network Based on Sensitivity CONTROL:v7 14.1 DESCRIPTION:Segment the network based on the label or classification level of the information stored on the servers, locate all sensitive information on separated Virtual Local Area Networks (VLANs).; | L9: 12.2 | P9: X | Q9: X | R9: 14.1 | V9: X | W9: X | Y9: By default, Azure Databricks uses a Databricks-Managed VNet.
A10: 2.1 | B10: 2.1.2 | C10: Ensure that network security groups are configured for Databricks subnets | D10: Automated | E10: Network Security Groups (NSGs) should be implemented to control inbound and outbound traffic to Azure Databricks subnets, ensuring only authorized communication. NSGs operate using a rule-based model that includes both explicit allow/deny rules and an implicit deny at the end of the rule list. This means that any traffic not explicitly allowed is automatically denied. To ensure secure and predictable behavior, NSGs should be configured with explicit deny rules for known unwanted traffic, in addition to the default implicit deny, to improve visibility and auditability of blocked traffic. This approach helps enforce least privilege and minimizes the risk of unauthorized access to Databricks resources. | F10: Using NSGs with both explicit allow and deny rules provides clear documentation and control over permitted and prohibited traffic. While Azure NSGs implicitly deny all traffic not explicitly allowed, defining explicit deny rules for known malicious or unnecessary sources enhances clarity, simplifies troubleshooting, and supports compliance audits. This layered approach strengthens the security posture of Databricks environments by ensuring only essential communication is permitted. | G10: '- NSGs require ongoing maintenance to ensure rule accuracy and alignment with evolving business and security requirements. - Misconfigured NSGs—especially overly broad allow rules or missing explicit denies—can inadvertently expose Databricks resources or block legitimate traffic. - Relying solely on implicit deny may obscure the intent behind traffic restrictions, making it harder to audit or troubleshoot network behavior. | H10: **Remediate from Azure Portal** 1. Assign NSG to Databricks subnets under Networking > NSG Settings. | I10: **Audit from Azure Portal** 1. Navigate to Virtual Networks > Subnets, and review NSG assignments. **Audit from Azure CLI** ``` az network nsg list --query "[].{Name:name, Rules:securityRules}" ``` **Audit from PowerShell** ``` Get-AzNetworkSecurityGroup -ResourceGroupName <resource-group-name> ``` | K10: TITLE:Implement and Manage a Firewall on Servers CONTROL:v8 4.4 DESCRIPTION:Implement and manage a firewall on servers, where supported. Example implementations include a virtual firewall, operating system firewall, or a third-party firewall agent.;TITLE:Apply Host-based Firewalls or Port Filtering CONTROL:v7 9.4 DESCRIPTION:Apply host-based firewalls or port filtering tools on end systems, with a default-deny rule that drops all traffic except those services and ports that are explicitly allowed.; | L10: 4.4 | O10: X | P10: X | Q10: X | R10: 9.4 | U10: X | V10: X | W10: X | X10: https://learn.microsoft.com/en-us/security/benchmark/azure/baselines/azure-databricks-security-baseline:https://learn.microsoft.com/en-us/azure/databricks/security/network/classic/vnet-inject#network-security-group-rules | Y10: By default, Databricks subnets do not have NSGs assigned.
A11: 2.1 | B11: 2.1.4 | C11: Ensure that users and groups are synced from Microsoft Entra ID to Azure Databricks | D11: Manual | E11: To ensure centralized identity and access management, users and groups from Microsoft Entra ID should be synchronized with Azure Databricks. This is achieved through SCIM provisioning, which automates the creation, update, and deactivation of users and groups in Databricks based on Entra ID assignments. Enabling this integration ensures that access controls in Databricks remain consistent with corporate identity governance policies, reducing the risk of orphaned accounts, stale permissions, and unauthorized access. | F11: Syncing users and groups from Microsoft Entra ID centralizes access control, enforces the least privilege principle by automatically revoking unnecessary access, reduces administrative overhead by eliminating manual user management, and ensures auditability and compliance with industry regulations. | G11: SCIM provisioning requires role mapping to avoid misconfigured user privileges. | H11: **Remediate from Azure Portal** Enable provisioning in Azure Portal: 1. Go to `Microsoft Entra ID`. 1. Under `Manage`, click `Enterprise applications`. 1. Click the name of the Azure Databricks SCIM application. 1. Under `Provisioning`, select `Automatic` and enter the SCIM endpoint and API token from Databricks. Enable provisioning in Databricks: 5. Navigate to `Admin Console` > `Identity and Access Management`. 6. Enable SCIM provisioning and generate an API token. Configure role assignments: 7. Ensure groups from Entra ID are mapped to appropriate Databricks roles. 8. Restrict administrative privileges to designated security groups. Regularly monitor sync logs: 9. Periodically review sync logs in Microsoft Entra ID and Databricks Admin Console. 10. Configure Azure Monitor alerts for provisioning failures. Disable manual user creation in Databricks: 11. Ensure that all user management is controlled via SCIM sync from Entra ID. 12. Disable personal access token usage for authentication. **Remediate from Azure CLI** Enable SCIM User and Group Provisioning in Azure Databricks: ``` az ad app update --id <databricks-app-id> --set provisioning.provisioningMode=Automatic ``` | I11: **Audit from Azure Portal** Verify SCIM provisioning is enabled: 1. Go to `Microsoft Entra ID`. 1. Under `Manage`, click `Enterprise applications`. 1. Click the name of the Azure Databricks SCIM application. 1. Under `Provisioning`, confirm that SCIM provisioning is enabled and running. Check user sync status in Azure Portal: 5. Under `Provisioning Logs`, verify the last successful sync and any failed entries. Check user sync status in Databricks: 6. Go to `Admin Console` > `Identity and Access Management`. 7. Confirm that Users and Groups match those assigned in Microsoft Entra ID. Ensure role-based access control (RBAC) mapping is correct: 8. Verify that users are assigned appropriate Databricks roles (e.g. Admin, User, Contributor). 9. Confirm that groups are mapped to workspace access roles. | K11: TITLE:Centralize Account Management CONTROL:v8 5.6 DESCRIPTION:Centralize account management through a directory or identity service.;TITLE:Configure Centralized Point of Authentication CONTROL:v7 16.2 DESCRIPTION:Configure access for all accounts through as few centralized points of authentication as possible, including network, security, and cloud systems.; | L11: 5.6 | P11: X | Q11: X | R11: 16.2 | V11: X | W11: X | X11: https://learn.microsoft.com/en-us/azure/databricks/administration-guide/users-groups/scim/aad | Y11: By default, Azure Databricks does not sync users and groups from Microsoft Entra ID.
A12: 2.1 | B12: 2.1.5 | C12: Ensure that Unity Catalog is configured for Azure Databricks | D12: Manual | E12: Unity Catalog is a centralized governance model for managing and securing data in Azure Databricks. It provides fine-grained access control to databases, tables, and views using Microsoft Entra ID identities. Unity Catalog also enhances data lineage, audit logging, and compliance monitoring, making it a critical component for security and governance. | F12: * Enforces centralized access control policies and reduces data security risks. * Enables identity-based authentication via Microsoft Entra ID. * Improves compliance with industry regulations (e.g. GDPR, HIPAA, SOC 2) by providing audit logs and access visibility. * Prevents unauthorized data access through table-, row-, and column-level security (RLS & CLS). | G12: * Improperly configured permissions may lead to data exfiltration or unauthorized access. * Unity Catalog requires structured governance policies to be effective and prevent overly permissive access. | H12: Use the remediation procedure written in this article: https://learn.microsoft.com/en-us/azure/databricks/data-governance/unity-catalog/get-started. | I12: Method 1: Verify unity catalog deployment: 1. As an Azure Databricks account admin, log into the account console. 1. Click Workspaces. 1. Find your workspace and check the Metastore column. If a metastore name is present, your workspace is attached to a Unity Catalog metastore and therefore enabled for Unity Catalog. Method 2: Run a SQL query to confirm Unity Catalog enablement Run the following SQL query in the SQL query editor or a notebook that is attached to a Unity Catalog-enabled compute resource. No admin role is required. ``` SELECT CURRENT_METASTORE(); ``` If the query returns a metastore ID like the following, then your workspace is attached to a Unity Catalog metastore and therefore enabled for Unity Catalog. | K12: TITLE:Centralize Account Management CONTROL:v8 5.6 DESCRIPTION:Centralize account management through a directory or identity service.;TITLE:Centralize Access Control CONTROL:v8 6.7 DESCRIPTION:Centralize access control for all enterprise assets through a directory service or SSO provider, where supported.;TITLE:Configure Centralized Point of Authentication CONTROL:v7 16.2 DESCRIPTION:Configure access for all accounts through as few centralized points of authentication as possible, including network, security, and cloud systems.; | L12: 5.6 | M12: 6.7 | P12: X | Q12: X | R12: 16.2 | V12: X | W12: X | X12: https://learn.microsoft.com/en-us/azure/databricks/data-governance/unity-catalog/:https://learn.microsoft.com/en-us/azure/databricks/admin/users-groups/:https://learn.microsoft.com/en-us/azure/databricks/data-governance/unity-catalog/enable-workspaces | Y12: New workspaces have Unity Catalog enabled by default. Existing workspaces may require manual enablement.
A13: 2.1 | B13: 2.1.6 | C13: Ensure that usage is restricted and expiry is enforced for Databricks personal access tokens | D13: Manual | E13: Databricks personal access tokens (PATs) provide API-based authentication for users and applications. By default, users can generate API tokens without expiration, leading to potential security risks if tokens are leaked, improperly stored, or not rotated regularly. To mitigate these risks, administrators should: * Restrict token creation to approved users and service principals. * Enforce expiration policies to prevent long-lived tokens. * Monitor token usage and revoke unused or compromised tokens. | F13: Restricting usage and enforcing expiry for personal access tokens reduces exposure to long-lived tokens, minimizes the risk of API abuse if compromised, and aligns with security best practices through controlled issuance and enforced expiry. | G13: If revoked improperly, applications relying on these tokens may fail, requiring a remediation plan for token rotation. Increased administrative effort is required to track and manage API tokens effectively. | H13: **Remediate from Azure Portal** Disable personal access tokens: If your workspace does not require PATs, you can disable them entirely to prevent their use.​ 1. Navigate to your Azure Databricks workspace. 1. Click the `Settings` icon and select `Admin Console`. 1. Go to the `Advanced` tab. 1. Under `Personal Access Tokens`, toggle the setting to `Disabled`. Databricks CLI: ``` databricks workspace-conf set-status --json '{"enableTokens": "false"}' ``` Control who can create and use personal access tokens: Define which users or groups are authorized to create and utilize PATs.​ 1. Navigate to your Azure Databricks workspace. 1. Click the `Settings` icon and select `Admin Console`. 1. Go to the `Advanced` tab. 1. Click on `Personal Access Tokens` and then `Permissions`. 1. Assign the appropriate permissions (e.g. No Permissions, Can Use, Can Manage) to users or groups. Set maximum lifetime for new personal access tokens: Limit the validity period of new tokens to reduce potential misuse.​ Databricks CLI: ``` databricks workspace-conf set-status --json '{"maxTokenLifetimeDays": "90"}' ``` Monitor and revoke personal access tokens: Periodically review active tokens and revoke any that are unnecessary or potentially compromised.​ Databricks CLI: ``` databricks token list ``` ``` databricks token delete --token-id <token-id> ``` Transition to OAuth for enhanced security: Utilize OAuth tokens for authentication, offering improved security features over PATs. | I13: Azure Databricks administrators can monitor and revoke personal access tokens within their workspace. Detailed instructions are available in the "Monitor and Revoke Personal Access Tokens" section of the Microsoft documentation: https://learn.microsoft.com/en-us/azure/databricks/admin/access-control/tokens. To evaluate the usage of personal access tokens in your Azure Databricks account, you can utilize the provided notebook that lists all PATs not rotated or updated in the last 90 days, allowing you to identify tokens that may require revocation. This process is detailed here: https://learn.microsoft.com/en-us/azure/databricks/admin/access-control/tokens. Implementing diagnostic logging provides a comprehensive reference of audit log services and events, enabling you to track activities related to personal access tokens. More information can be found in the diagnostic log reference section: https://learn.microsoft.com/en-us/azure/databricks/admin/account-settings/audit-logs. | K13: TITLE:Establish an Access Revoking Process CONTROL:v8 6.2 DESCRIPTION:Establish and follow a process, preferably automated, for revoking access to enterprise assets, through disabling accounts immediately upon termination, rights revocation, or role change of a user. Disabling accounts, instead of deleting accounts, may be necessary to preserve audit trails.;TITLE:Establish Process for Revoking Access CONTROL:v7 16.7 DESCRIPTION:Establish and follow an automated process for revoking system access by disabling accounts immediately upon termination or change of responsibilities of an employee or contractor . Disabling these accounts, instead of deleting accounts, allows preservation of audit trails.; | L13: 6.2 | O13: X | P13: X | Q13: X | R13: 16.7 | V13: X | W13: X | X13: https://learn.microsoft.com/en-us/azure/databricks/administration-guide/access-control/tokens:https://learn.microsoft.com/en-us/azure/databricks/dev-tools/auth/ | Y13: By default, personal access tokens are enabled and users can create the Personal access token and their expiry time.
A14: 2.1 | B14: 2.1.7 | C14: Ensure that diagnostic log delivery is configured for Azure Databricks | D14: Automated | E14: Azure Databricks Diagnostic Logging provides insights into system operations, user activities, and security events within a Databricks workspace. Enabling diagnostic logs helps organizations: * Detect security threats by logging access, job executions, and cluster activities. * Ensure compliance with industry regulations such as SOC 2, HIPAA, and GDPR. * Monitor operational performance and troubleshoot issues proactively. | F14: Diagnostic logging provides visibility into security and operational activities within Databricks workspaces while maintaining an audit trail for forensic investigations, and it supports compliance with regulatory standards that require logging and monitoring. | G14: Logs consume storage and may require additional monitoring tools, leading to increased operational overhead and costs. Incomplete log configurations may result in missing critical events, reducing monitoring effectiveness. | H14: **Remediate from Azure Portal** Enable diagnostic logging for Azure Databricks: 1. Navigate to your Azure Databricks workspace. 1. In the left-hand menu, select `Monitoring` > `Diagnostic settings`. 1. Click `+ Add diagnostic setting`. 1. Under `Category details`, select the log categories you wish to capture, such as AuditLogs, Clusters, Notebooks, and Jobs. 1. Choose a destination for the logs: - `Log Analytics workspace`: For advanced querying and monitoring. - `Storage account`: For long-term retention. - `Event Hub`: For integration with third-party systems. 1. Provide a `Name` for the diagnostic setting. 1. Click `Save`. Implement log retention policies: 1. Navigate to your Log Analytics workspace. 1. Under `General`, select `Usage and estimated costs`. 1. Click `Data Retention`. 1. Adjust the retention period slider to the desired number of days (up to 730 days). 1. Click `OK`. Monitor logs for anomalies: 1. Navigate to `Azure Monitor`. 1. Select `Alerts` > `+ New alert rule`. 1. Under `Scope`, specify the Databricks resource. 1. Define `Condition` based on log queries that identify anomalies (e.g. unauthorized access attempts). 1. Configure `Actions` to notify stakeholders or trigger automated responses. 1. Provide an Alert rule `name` and `description`. 1. Click `Create alert rule`. **Remediate from Azure CLI** Enable diagnostic logging for Azure Databricks: ``` az monitor diagnostic-settings create --name "DatabricksLogging" --resource <databricks-resource-id> --logs '[{"category": "accounts", "enabled": true}, {"category": "Clusters", "enabled": true}, {"category": "Notebooks", "enabled": true}, {"category": "Jobs", "enabled": true}]' --workspace <log-analytics-id> ``` Implement log retention policies: ``` az monitor log-analytics workspace update --resource-group <resource-group> --name <log-analytics-name> --retention-time 365 ``` Monitor logs for anomalies: ``` az monitor activity-log alert create --name "DatabricksAnomalyAlert" --resource-group <resource-group> --scopes <databricks-resource-id> --condition "contains 'UnauthorizedAccess'" ``` | I14: **Audit from Azure Portal** Check if diagnostic logging is enabled for the Databricks workspace: 1. Go to `Azure Databricks`. 1. Select a workspace. 1. In the left-hand menu, select `Monitoring` > `Diagnostic settings`. 1. Verify if a diagnostic setting is configured. If not, diagnostic logging is not enabled. Ensure that logging is enabled for the following categories:​ * `accounts`: User account activities. * `Filesystem`: Databricks Filesystem Logs * `clusters`: Cluster state changes and errors. * `notebook`: Execution events. * `jobs`: Job execution tracking. Verify that logs are being sent to one or more of the following destinations:​ * `Azure Log Analytics workspace`: For analysis and querying. * `Azure Storage Account`: For long-term retention. * `Azure Event Hubs`: For integration with SIEM tools. **Audit from Azure CLI** Check if diagnostic logging is enabled for the Databricks workspace: ``` az monitor diagnostic-settings list --resource <databricks-resource-id> ``` If the output is empty, no diagnostic settings are configured. Verify log categories being collected: ``` az monitor diagnostic-settings show --name <setting-name> --resource <databricks-resource-id> ``` Review the output to confirm that the necessary log categories are enabled. Check if logs are stored securely in an approved location: ``` az monitor diagnostic-settings list --resource <databricks-resource-id> ``` Review the storageAccountId, workspaceId, and eventHubAuthorizationRuleId fields in the output to confirm the log destinations. **Audit from PowerShell** Check if diagnostic logging is enabled for the Databricks workspace: ``` Get-AzDiagnosticSetting -ResourceId <databricks-resource-id> ``` An empty result indicates that diagnostic logging is not enabled. **Audit from Azure Policy** If referencing a digital copy of this Benchmark, clicking a Policy ID will open a link to the associated Policy definition in Azure. If referencing a printed copy, you can search Policy IDs from this URL: https://portal.azure.com/#view/Microsoft_Azure_Policy/PolicyMenuBlade/~/Definitions - **Policy ID:** [138ff14d-b687-4faa-a81c-898c91a87fa2](https://portal.azure.com/#view/Microsoft_Azure_Policy/PolicyDetailBlade/definitionId/%2Fproviders%2FMicrosoft.Authorization%2FpolicyDefinitions%2F138ff14d-b687-4faa-a81c-898c91a87fa2) **- Name:** 'Resource logs in Azure Databricks Workspaces should be enabled' | J14: * Ensure that the Azure Databricks workspace is on the Premium plan to utilize diagnostic logging features. * Regularly review and update alert rules to adapt to evolving security threats and operational requirements. | K14: TITLE:Collect Audit Logs CONTROL:v8 8.2 DESCRIPTION:Collect audit logs. Ensure that logging, per the enterprise’s audit log management process, has been enabled across enterprise assets.;TITLE:Activate audit logging CONTROL:v7 6.2 DESCRIPTION:Ensure that local logging has been enabled on all systems and networking devices.; | L14: 8.2 | O14: X | P14: X | Q14: X | R14: 6.2 | U14: X | V14: X | W14: X | X14: https://learn.microsoft.com/en-us/azure/databricks/admin/account-settings/audit-log-delivery:https://learn.microsoft.com/en-us/troubleshoot/azure/azure-monitor/log-analytics/billing/configure-data-retention:https://docs.azure.cn/en-us/databricks/admin/account-settings/audit-logs:https://learn.microsoft.com/en-us/azure/azure-monitor/reference/supported-logs/microsoft-databricks-workspaces-logs
A15: 2.1 | B15: 2.1.9 | C15: Ensure 'No Public IP' is set to 'Enabled' | D15: Automated | E15: Enable secure cluster connectivity (also known as no public IP) on Azure Databricks workspaces to ensure that clusters do not have public IP addresses and communicate with the control plane over a secure connection. | F15: Enabling secure cluster connectivity limits exposure to the public internet, improving security and reducing the risk of external attacks. | G15: Enabling secure cluster connectivity requires careful network configuration. Before secure cluster connectivity can be enabled, Azure Databricks workspaces must be deployed in a customer-managed virtual network (VNet injection)—refer to the recommendation `Ensure that Azure Databricks is deployed in a customer-managed virtual network (VNet)`. | H15: **Remediate from Azure Portal** 1. Go to `Azure Databricks`. 1. Click the name of a workspace. 1. Under `Settings`, click `Networking`. 1. Under `Network access`, next to `Deploy Azure Databricks workspace with Secure Cluster Connectivity (No Public IP)`, click the radio button next to `Enabled`. 1. Click `Save`. 1. Repeat steps 1-5 for each workspace requiring remediation. **Remediate from Azure CLI** For each workspace requiring remediation, run the following command to set `enableNoPublicIp` to `true`: ``` az databricks workspace update --resource-group <resource-group> --name <workspace> --enable-no-public-ip true ``` **Remediate from PowerShell** For each workspace requiring remediation, run the following command to set `EnableNoPublicIP` to `True`: ``` Update-AzDatabricksWorkspace -ResourceGroupName <resource-group> -Name <workspace> -EnableNoPublicIP ``` | I15: **Audit from Azure Portal** 1. Go to `Azure Databricks`. 1. Click the name of a workspace. 1. Under `Settings`, click `Networking`. 1. Under `Network access`, ensure that `Deploy Azure Databricks workspace with Secure Cluster Connectivity (No Public IP)` is set to `Enabled`. 1. Repeat steps 1-4 for each workspace. **Audit from Azure CLI** Run the following command to list workspaces: ``` az databricks workspace list ``` For each workspace, run the following command to get the `enableNoPublicIp` setting: ``` az databricks workspace show --resource-group <resource-group> --name <workspace> --query parameters.enableNoPublicIp.value ``` Ensure that `true` is returned. **Audit from PowerShell** Run the following command to list workspaces: ``` Get-AzDatabricksWorkspace ``` Run the following command to get the workspace in a resource group with a given name: ``` $workspace = Get-AzDatabricksWorkspace -ResourceGroupName <resource-group> -Name <workspace> ``` Run the following command to get the `EnableNoPublicIp` setting: ``` $workspace.EnableNoPublicIP ``` Ensure that `True` is returned. Repeat for each workspace. **Audit from Azure Policy** If referencing a digital copy of this Benchmark, clicking a Policy ID will open a link to the associated Policy definition in Azure. If referencing a printed copy, you can search Policy IDs from this URL: https://portal.azure.com/#view/Microsoft_Azure_Policy/PolicyMenuBlade/~/Definitions - **Policy ID:** [51c1490f-3319-459c-bbbc-7f391bbed753](https://portal.azure.com/#view/Microsoft_Azure_Policy/PolicyDetailBlade/definitionId/%2Fproviders%2FMicrosoft.Authorization%2FpolicyDefinitions%2F51c1490f-3319-459c-bbbc-7f391bbed753) **- Name:** 'Azure Databricks Clusters should disable public IP' | K15: TITLE:Configure Data Access Control Lists CONTROL:v8 3.3 DESCRIPTION:Configure data access control lists based on a user’s need to know. Apply data access control lists, also known as access permissions, to local and remote file systems, databases, and applications.;TITLE:Protect Information through Access Control Lists CONTROL:v7 14.6 DESCRIPTION:Protect all information stored on systems with file system, network share, claims, application, or database specific access control lists. These controls will enforce the principle that only authorized individuals should have access to the information based on their need to access the information as a part of their responsibilities.; | L15: 3.3 | O15: X | P15: X | Q15: X | R15: 14.6 | U15: X | V15: X | W15: X | X15: https://learn.microsoft.com/en-us/azure/databricks/security/network/classic/secure-cluster-connectivity:https://learn.microsoft.com/en-us/cli/azure/databricks/workspace:https://learn.microsoft.com/en-us/powershell/module/az.databricks | Y15: `No Public IP` is set to `Enabled` by default.
A16: 2.1 | B16: 2.1.10 | C16: Ensure 'Allow Public Network Access' is set to 'Disabled' | D16: Automated | E16: Disable public network access to prevent exposure to the internet and reduce the risk of unauthorized access. Use private endpoints to securely manage access within trusted networks. | F16: Disabling public network access improves security by ensuring that Azure Databricks workspaces are not exposed on the public internet. | G16: **NOTE:** Prior to disabling public network access, it is strongly recommended that, for each workspace, either: - virtual network integration is completed as described in **"Ensure that Azure Databricks is deployed in a customer-managed virtual network (VNet)"** OR - private endpoints/links are set up as described in **"Ensure private endpoints are used to access Azure Databricks workspaces."** Disabling public network access restricts access to the service. This enhances security but will require the configuration of a virtual network and/or private endpoints for any services or users needing access within trusted networks. Before public network access can be disabled, Azure Databricks workspaces must be deployed in a customer-managed virtual network (VNet injection)—refer to the recommendation `Ensure that Azure Databricks is deployed in a customer-managed virtual network (VNet)`, and `requiredNsgRules` must be set to a value other than `AllRules`. | H16: **Remediate from Azure Portal** 1. Go to `Azure Databricks`. 1. Click the name of a workspace. 1. Under `Settings` click `Networking`. 1. Under `Network access`, next to `Allow Public Network Access`, click the radio button next to `Disabled`. 1. Click `Save`. 1. Repeat steps 1-5 for each workspace requiring remediation. **Remediate from Azure CLI** For each workspace requiring remediation, run the following command to set `publicNetworkAccess` to `Disabled`: ``` az databricks workspace update --resource-group <resource-group> --name <workspace> --public-network-access Disabled ``` **Remediate from PowerShell** For each workspace requiring remediation, run the following command to set `PublicNetworkAccess` to `Disabled`: ``` Update-AzDatabricksWorkspace -ResourceGroupName <resource-group> -Name <workspace> -PublicNetworkAccess Disabled ``` | I16: **Audit from Azure Portal** 1. Go to `Azure Databricks`. 1. Click the name of a workspace. 1. Under `Settings` click `Networking`. 1. Under `Network access`, ensure `Allow Public Network Access` is set to `Disabled`. 1. Repeat steps 1-4 for each workspace. **Audit from Azure CLI** Run the following command to list workspaces: ``` az databricks workspace list ``` For each workspace, run the following command to get the `publicNetworkAccess` setting: ``` az databricks workspace show --resource-group <resource-group> --name <workspace> --query publicNetworkAccess ``` Ensure that `"Disabled"` is returned. **Audit from PowerShell** Run the following command to list workspaces: ``` Get-AzDatabricksWorkspace ``` Run the following command to get the workspace in a resource group with a given name: ``` $workspace = Get-AzDatabricksWorkspace -ResourceGroupName <resource-group> -Name <workspace> ``` Run the following command to get the `PublicNetworkAccess` setting: ``` $workspace.PublicNetworkAccess ``` Ensure that `Disabled` is returned. Repeat for each workspace. **Audit from Azure Policy** If referencing a digital copy of this Benchmark, clicking a Policy ID will open a link to the associated Policy definition in Azure. If referencing a printed copy, you can search Policy IDs from this URL: https://portal.azure.com/#view/Microsoft_Azure_Policy/PolicyMenuBlade/~/Definitions - **Policy ID:** [0e7849de-b939-4c50-ab48-fc6b0f5eeba2](https://portal.azure.com/#view/Microsoft_Azure_Policy/PolicyDetailBlade/definitionId/%2Fproviders%2FMicrosoft.Authorization%2FpolicyDefinitions%2F0e7849de-b939-4c50-ab48-fc6b0f5eeba2) **- Name:** 'Azure Databricks Workspaces should disable public network access' | J16: This recommendation is based on the Common Reference Recommendation `Ensure public network access is Disabled`, from the `Common Reference Recommendations > Networking > Virtual Networks (VNets)` section. | K16: TITLE:Configure Data Access Control Lists CONTROL:v8 3.3 DESCRIPTION:Configure data access control lists based on a user’s need to know. Apply data access control lists, also known as access permissions, to local and remote file systems, databases, and applications.;TITLE:Protect Information through Access Control Lists CONTROL:v7 14.6 DESCRIPTION:Protect all information stored on systems with file system, network share, claims, application, or database specific access control lists. These controls will enforce the principle that only authorized individuals should have access to the information based on their need to access the information as a part of their responsibilities.; | L16: 3.3 | O16: X | P16: X | Q16: X | R16: 14.6 | U16: X | V16: X | W16: X | X16: https://learn.microsoft.com/en-us/cli/azure/databricks/workspace:https://learn.microsoft.com/en-us/powershell/module/az.databricks | Y16: `Allow Public Network Access` is set to `Enabled` by default.
A17: 3 | C17: Compute Services | E17: **SERVICE CATEGORY BENCHMARK AVAILABLE**: - "CIS Microsoft Azure Compute Services Benchmark" To better understand the relationship between the Foundations Benchmark and Services Benchmarks, please read the "Introduction" section of this document. `PARTIAL RELOCATION - BE ADVISED!` Some recommendations previously covered in the CIS Microsoft Azure Foundations Benchmark (this document) related to Compute services have been relocated to a Benchmark titled **CIS Microsoft Azure Compute Services Benchmark**. This Compute Services section now provides a **foundational set** of secure configuration recommendations for products from Azure Product Directory's "Compute" category of services. After applying foundational recommendations, take inventory of the entire set of Compute Services in use by your organization, then look to the Benchmarks section of the CIS Microsoft Azure Community (https://workbench.cisecurity.org/communities/72) for defense-in-depth guidance for those specific services in the **CIS Microsoft Azure Compute Services Benchmark**. Services addressed in the **CIS Microsoft Azure Compute Services Benchmark**: - App Service - Azure Container Instances - Azure CycleCloud - Azure Dedicated Host - Azure Functions - Azure Kubernetes Service (AKS) - Azure Quantum - Azure Service Fabric - Azure Spot Virtual Machines - Azure Spring Apps - Azure Virtual Desktop - Azure VM Image Builder - Azure VMware Solution - Batch - Cloud Services - Linux Virtual Machines - SQL Server on Azure Virtual Machines - Static Web Apps - Virtual Machine Scale Sets - Virtual Machines Azure Product Directory Reference: https://azure.microsoft.com/en-us/products#compute **FEEDBACK REQUEST:** Is there a specific service or recommendation in this section that you'd like to see addressed or improved? Let us know by making a ticket or starting a discussion in the CIS Microsoft Azure Community (https://workbench.cisecurity.org/communities/72).
A18: 3.1 | C18: Virtual Machines | E18: This section covers security recommendations to follow for the configuration of Virtual Machines on an Azure subscription.
A19: 4 | C19: Database Services (reference) | E19: **SERVICE CATEGORY BENCHMARK AVAILABLE**: - "CIS Microsoft Azure Database Services Benchmark" To better understand the relationship between the Foundations Benchmark and Services Benchmarks, please read the "Introduction" section of this document. `FULL RELOCATION - BE ADVISED!` **- ALL -** recommendations previously covered in the CIS Microsoft Azure Foundations Benchmark (this document) related to products in the Database category of services have been relocated to a Benchmark titled **CIS Microsoft Azure Database Services Benchmark**. This section now serves only as a reference. Services addressed in the **CIS Microsoft Azure Database Services Benchmark**: - Azure Cache for Redis - Azure Cosmos DB - Azure Data Factory - Azure Database for MariaDB - Azure Database for MySQL - Azure Database for PostgreSQL - Azure Database Migration Service - Azure SQL - Azure SQL Database - Azure SQL Edge - Azure SQL Managed Instance - SQL Server on Azure Virtual Machines - Table Storage - Azure Managed Instance for Apache Cassandra - Azure confidential ledger Azure Product Directory Reference: https://azure.microsoft.com/en-us/products#databases **FEEDBACK REQUEST:** Is there a specific service or recommendation in this section that you'd like to see addressed or improved? Let us know by making a ticket or starting a discussion in the CIS Microsoft Azure Community (https://workbench.cisecurity.org/communities/72).
A20: 5 | C20: Identity Services | E20: To better understand the relationship between the Foundations Benchmark and Services Benchmarks, please read the "Introduction" section of this document. This section covers security best practice recommendations for products in the Azure Identity services category. Azure Product Directory Reference: https://azure.microsoft.com/en-us/products#identity **FEEDBACK REQUEST:** Is there a specific service or recommendation in this section that you'd like to see addressed or improved? Let us know by making a ticket or starting a discussion in the CIS Microsoft Azure Community (https://workbench.cisecurity.org/communities/72).
A21: 5 | B21: 5.4 | C21: Ensure that 'Restrict non-admin users from creating tenants' is set to 'Yes' | D21: Automated | E21: Require administrators or appropriately delegated users to create new tenants. | F21: It is recommended to only allow an administrator to create new tenants. This prevent users from creating new Microsoft Entra ID or Azure AD B2C tenants and ensures that only authorized users are able to do so. | G21: Enforcing this setting will ensure that only authorized users are able to create new tenants. | H21: **Remediate from Azure Portal** 1. From Azure Home select the Portal Menu 1. Select `Microsoft Entra ID` 1. Under `Manage`, select `Users` 1. Under `Manage`, select `User settings` 1. Set `Restrict non-admin users from creating tenants ` to `Yes` 1. Click `Save` **Remediate from PowerShell** ``` Import-Module Microsoft.Graph.Identity.SignIns Connect-MgGraph -Scopes 'Policy.ReadWrite.Authorization' Select-MgProfile -Name beta $params = @{ DefaultUserRolePermissions = @{ AllowedToCreateTenants = $false } } Update-MgPolicyAuthorizationPolicy -AuthorizationPolicyId -BodyParameter $params ``` | I21: **Audit from Azure Portal** 1. From Azure Home select the Portal Menu 1. Select `Microsoft Entra ID` 1. Under `Manage`, select `Users` 1. Under `Manage`, select `User settings` 1. Ensure that `Restrict non-admin users from creating tenants` is set to `Yes` **Audit from PowerShell** ``` Import-Module Microsoft.Graph.Identity.SignIns Connect-MgGraph -Scopes 'Policy.ReadWrite.Authorization' Get-MgPolicyAuthorizationPolicy | Select-Object -ExpandProperty DefaultUserRolePermissions | Format-List ``` Review the "DefaultUserRolePermissions" section of the output. Ensure that `AllowedToCreateTenants` is not `"True"`. | K21: TITLE:Define and Maintain Role-Based Access Control CONTROL:v8 6.8 DESCRIPTION:Define and maintain role-based access control, through determining and documenting the access rights necessary for each role within the enterprise to successfully carry out its assigned duties. Perform access control reviews of enterprise assets to validate that all privileges are authorized, on a recurring schedule at a minimum annually, or more frequently.;TITLE:Protect Information through Access Control Lists CONTROL:v7 14.6 DESCRIPTION:Protect all information stored on systems with file system, network share, claims, application, or database specific access control lists. These controls will enforce the principle that only authorized individuals should have access to the information based on their need to access the information as a part of their responsibilities.; | L21: 6.8 | Q21: X | R21: 14.6 | U21: X | V21: X | W21: X | X21: https://learn.microsoft.com/en-us/entra/fundamentals/users-default-permissions:https://learn.microsoft.com/en-us/entra/identity/role-based-access-control/permissions-reference#tenant-creator:https://blog.admindroid.com/disable-users-creating-new-azure-ad-tenants-in-microsoft-365/
